-------------||time:2019-07-20T21:33:00.114252+0600||level:ERROR||-------------
401 {'message': 'Bad credentials', 'documentation_url': 'https://developer.github.com/v3'}

Traceback (most recent call last):
  File "/home/redowan/code/protomate/protomate/script.py", line 277, in <module>
    main()
  File "/home/redowan/code/protomate/protomate/script.py", line 270, in main
    g, user = protomate.authentication(github_username, github_password)
> File "/home/redowan/code/protomate/protomate/script.py", line 139, in authentication
    self.user.login
  File "/home/redowan/.local/lib/python3.7/site-packages/github/AuthenticatedUser.py", line 230, in login
    self._completeIfNotSet(self._login)
  File "/home/redowan/.local/lib/python3.7/site-packages/github/GithubObject.py", line 263, in _completeIfNotSet
    self._completeIfNeeded()
  File "/home/redowan/.local/lib/python3.7/site-packages/github/GithubObject.py", line 267, in _completeIfNeeded
    self.__complete()
  File "/home/redowan/.local/lib/python3.7/site-packages/github/GithubObject.py", line 272, in __complete
    self._url.value
  File "/home/redowan/.local/lib/python3.7/site-packages/github/Requester.py", line 275, in requestJsonAndCheck
    return self.__check(*self.requestJson(verb, url, parameters, headers, input, self.__customConnection(url)))
  File "/home/redowan/.local/lib/python3.7/site-packages/github/Requester.py", line 286, in __check
    raise self.__createException(status, responseHeaders, output)
github.GithubException.BadCredentialsException: 401 {'message': 'Bad credentials', 'documentation_url': 'https://developer.github.com/v3'}
-------------||time:2019-07-20T22:00:49.655079+0600||level:ERROR||-------------
401 {'message': 'Requires authentication', 'documentation_url': 'https://developer.github.com/v3/users/#get-the-authenticated-user'}

Traceback (most recent call last):
  File "/home/redowan/code/protomate/protomate/script.py", line 277, in <module>
    main()
  File "/home/redowan/code/protomate/protomate/script.py", line 270, in main
    g, user = protomate.authentication(github_username, github_password)
> File "/home/redowan/code/protomate/protomate/script.py", line 139, in authentication
    self.user.login
  File "/home/redowan/.local/lib/python3.7/site-packages/github/AuthenticatedUser.py", line 230, in login
    self._completeIfNotSet(self._login)
  File "/home/redowan/.local/lib/python3.7/site-packages/github/GithubObject.py", line 263, in _completeIfNotSet
    self._completeIfNeeded()
  File "/home/redowan/.local/lib/python3.7/site-packages/github/GithubObject.py", line 267, in _completeIfNeeded
    self.__complete()
  File "/home/redowan/.local/lib/python3.7/site-packages/github/GithubObject.py", line 272, in __complete
    self._url.value
  File "/home/redowan/.local/lib/python3.7/site-packages/github/Requester.py", line 275, in requestJsonAndCheck
    return self.__check(*self.requestJson(verb, url, parameters, headers, input, self.__customConnection(url)))
  File "/home/redowan/.local/lib/python3.7/site-packages/github/Requester.py", line 286, in __check
    raise self.__createException(status, responseHeaders, output)
github.GithubException.GithubException: 401 {'message': 'Requires authentication', 'documentation_url': 'https://developer.github.com/v3/users/#get-the-authenticated-user'}
-------------||time:2019-07-20T22:12:09.906936+0600||level:ERROR||-------------
401 {'message': 'Requires authentication', 'documentation_url': 'https://developer.github.com/v3/users/#get-the-authenticated-user'}

Traceback (most recent call last):
  File "/home/redowan/code/protomate/protomate/script.py", line 277, in <module>
    main()
  File "/home/redowan/code/protomate/protomate/script.py", line 270, in main
    g, user = protomate.authentication(github_username, github_password)
> File "/home/redowan/code/protomate/protomate/script.py", line 139, in authentication
    self.user.login
  File "/home/redowan/.local/lib/python3.7/site-packages/github/AuthenticatedUser.py", line 230, in login
    self._completeIfNotSet(self._login)
  File "/home/redowan/.local/lib/python3.7/site-packages/github/GithubObject.py", line 263, in _completeIfNotSet
    self._completeIfNeeded()
  File "/home/redowan/.local/lib/python3.7/site-packages/github/GithubObject.py", line 267, in _completeIfNeeded
    self.__complete()
  File "/home/redowan/.local/lib/python3.7/site-packages/github/GithubObject.py", line 272, in __complete
    self._url.value
  File "/home/redowan/.local/lib/python3.7/site-packages/github/Requester.py", line 275, in requestJsonAndCheck
    return self.__check(*self.requestJson(verb, url, parameters, headers, input, self.__customConnection(url)))
  File "/home/redowan/.local/lib/python3.7/site-packages/github/Requester.py", line 286, in __check
    raise self.__createException(status, responseHeaders, output)
github.GithubException.GithubException: 401 {'message': 'Requires authentication', 'documentation_url': 'https://developer.github.com/v3/users/#get-the-authenticated-user'}
-------------||time:2019-07-20T22:12:47.415586+0600||level:ERROR||-------------
401 {'message': 'Requires authentication', 'documentation_url': 'https://developer.github.com/v3/users/#get-the-authenticated-user'}

Traceback (most recent call last):
  File "/home/redowan/code/protomate/protomate/script.py", line 276, in <module>
    main()
  File "/home/redowan/code/protomate/protomate/script.py", line 269, in main
    g, user = protomate.authentication(github_username, github_password)
> File "/home/redowan/code/protomate/protomate/script.py", line 139, in authentication
    self.user.login
  File "/home/redowan/.local/lib/python3.7/site-packages/github/AuthenticatedUser.py", line 230, in login
    self._completeIfNotSet(self._login)
  File "/home/redowan/.local/lib/python3.7/site-packages/github/GithubObject.py", line 263, in _completeIfNotSet
    self._completeIfNeeded()
  File "/home/redowan/.local/lib/python3.7/site-packages/github/GithubObject.py", line 267, in _completeIfNeeded
    self.__complete()
  File "/home/redowan/.local/lib/python3.7/site-packages/github/GithubObject.py", line 272, in __complete
    self._url.value
  File "/home/redowan/.local/lib/python3.7/site-packages/github/Requester.py", line 275, in requestJsonAndCheck
    return self.__check(*self.requestJson(verb, url, parameters, headers, input, self.__customConnection(url)))
  File "/home/redowan/.local/lib/python3.7/site-packages/github/Requester.py", line 286, in __check
    raise self.__createException(status, responseHeaders, output)
github.GithubException.GithubException: 401 {'message': 'Requires authentication', 'documentation_url': 'https://developer.github.com/v3/users/#get-the-authenticated-user'}
