-------------||time:2019-09-09T14:51:55.369801+0600||level:ERROR||-------------
401 {'message': 'Bad credentials', 'documentation_url': 'https://developer.github.com/v3'}

Traceback (most recent call last):
  File "/home/redowan/code/protomate/protomate/script.py", line 46, in <module>
    main()
  File "/home/redowan/code/protomate/protomate/script.py", line 34, in main
    cli()
  File "/home/redowan/code/protomate/protomate/cli_prompts.py", line 58, in cli
    PASS_SAVED = is_pass_saved(github_username)
  File "/home/redowan/code/protomate/protomate/repo_auths.py", line 44, in is_pass_saved
    authentication(username, password)
> File "/home/redowan/code/protomate/protomate/repo_auths.py", line 29, in authentication
    user.login
  File "/home/redowan/code/protomate/venv/lib/python3.7/site-packages/github/AuthenticatedUser.py", line 230, in login
    self._completeIfNotSet(self._login)
  File "/home/redowan/code/protomate/venv/lib/python3.7/site-packages/github/GithubObject.py", line 303, in _completeIfNotSet
    self._completeIfNeeded()
  File "/home/redowan/code/protomate/venv/lib/python3.7/site-packages/github/GithubObject.py", line 307, in _completeIfNeeded
    self.__complete()
  File "/home/redowan/code/protomate/venv/lib/python3.7/site-packages/github/GithubObject.py", line 310, in __complete
    headers, data = self._requester.requestJsonAndCheck("GET", self._url.value)
  File "/home/redowan/code/protomate/venv/lib/python3.7/site-packages/github/Requester.py", line 326, in requestJsonAndCheck
    verb, url, parameters, headers, input, self.__customConnection(url)
  File "/home/redowan/code/protomate/venv/lib/python3.7/site-packages/github/Requester.py", line 349, in __check
    raise self.__createException(status, responseHeaders, output)
github.GithubException.BadCredentialsException: 401 {'message': 'Bad credentials', 'documentation_url': 'https://developer.github.com/v3'}
-------------||time:2019-09-09T15:13:32.502108+0600||level:ERROR||-------------
401 {'message': 'Bad credentials', 'documentation_url': 'https://developer.github.com/v3'}

Traceback (most recent call last):
  File "/home/redowan/.local/bin/protomate", line 10, in <module>
    sys.exit(main())
  File "/home/redowan/.local/lib/python3.7/site-packages/protomate/script.py", line 39, in main
    g, user = authentication(github_username, github_password)
> File "/home/redowan/.local/lib/python3.7/site-packages/protomate/repo_auths.py", line 29, in authentication
    user.login
  File "/home/redowan/.local/lib/python3.7/site-packages/github/AuthenticatedUser.py", line 230, in login
    self._completeIfNotSet(self._login)
  File "/home/redowan/.local/lib/python3.7/site-packages/github/GithubObject.py", line 265, in _completeIfNotSet
    self._completeIfNeeded()
  File "/home/redowan/.local/lib/python3.7/site-packages/github/GithubObject.py", line 269, in _completeIfNeeded
    self.__complete()
  File "/home/redowan/.local/lib/python3.7/site-packages/github/GithubObject.py", line 274, in __complete
    self._url.value
  File "/home/redowan/.local/lib/python3.7/site-packages/github/Requester.py", line 276, in requestJsonAndCheck
    return self.__check(*self.requestJson(verb, url, parameters, headers, input, self.__customConnection(url)))
  File "/home/redowan/.local/lib/python3.7/site-packages/github/Requester.py", line 287, in __check
    raise self.__createException(status, responseHeaders, output)
github.GithubException.BadCredentialsException: 401 {'message': 'Bad credentials', 'documentation_url': 'https://developer.github.com/v3'}
-------------||time:2019-09-09T15:21:44.768723+0600||level:ERROR||-------------
401 {'message': 'Bad credentials', 'documentation_url': 'https://developer.github.com/v3'}

Traceback (most recent call last):
  File "/home/redowan/code/protomate/protomate/script.py", line 46, in <module>
    main()
  File "/home/redowan/code/protomate/protomate/script.py", line 39, in main
    g, user = authentication(github_username, github_password)
> File "/home/redowan/code/protomate/protomate/repo_auths.py", line 29, in authentication
    user.login
  File "/home/redowan/code/protomate/venv/lib/python3.7/site-packages/github/AuthenticatedUser.py", line 230, in login
    self._completeIfNotSet(self._login)
  File "/home/redowan/code/protomate/venv/lib/python3.7/site-packages/github/GithubObject.py", line 303, in _completeIfNotSet
    self._completeIfNeeded()
  File "/home/redowan/code/protomate/venv/lib/python3.7/site-packages/github/GithubObject.py", line 307, in _completeIfNeeded
    self.__complete()
  File "/home/redowan/code/protomate/venv/lib/python3.7/site-packages/github/GithubObject.py", line 310, in __complete
    headers, data = self._requester.requestJsonAndCheck("GET", self._url.value)
  File "/home/redowan/code/protomate/venv/lib/python3.7/site-packages/github/Requester.py", line 326, in requestJsonAndCheck
    verb, url, parameters, headers, input, self.__customConnection(url)
  File "/home/redowan/code/protomate/venv/lib/python3.7/site-packages/github/Requester.py", line 349, in __check
    raise self.__createException(status, responseHeaders, output)
github.GithubException.BadCredentialsException: 401 {'message': 'Bad credentials', 'documentation_url': 'https://developer.github.com/v3'}
-------------||time:2019-09-09T15:22:46.565841+0600||level:ERROR||-------------
401 {'message': 'Bad credentials', 'documentation_url': 'https://developer.github.com/v3'}

Traceback (most recent call last):
  File "/home/redowan/code/protomate/protomate/script.py", line 46, in <module>
    main()
  File "/home/redowan/code/protomate/protomate/script.py", line 39, in main
    g, user = authentication(github_username, github_password)
> File "/home/redowan/code/protomate/protomate/repo_auths.py", line 29, in authentication
    user.login
  File "/home/redowan/code/protomate/venv/lib/python3.7/site-packages/github/AuthenticatedUser.py", line 230, in login
    self._completeIfNotSet(self._login)
  File "/home/redowan/code/protomate/venv/lib/python3.7/site-packages/github/GithubObject.py", line 303, in _completeIfNotSet
    self._completeIfNeeded()
  File "/home/redowan/code/protomate/venv/lib/python3.7/site-packages/github/GithubObject.py", line 307, in _completeIfNeeded
    self.__complete()
  File "/home/redowan/code/protomate/venv/lib/python3.7/site-packages/github/GithubObject.py", line 310, in __complete
    headers, data = self._requester.requestJsonAndCheck("GET", self._url.value)
  File "/home/redowan/code/protomate/venv/lib/python3.7/site-packages/github/Requester.py", line 326, in requestJsonAndCheck
    verb, url, parameters, headers, input, self.__customConnection(url)
  File "/home/redowan/code/protomate/venv/lib/python3.7/site-packages/github/Requester.py", line 349, in __check
    raise self.__createException(status, responseHeaders, output)
github.GithubException.BadCredentialsException: 401 {'message': 'Bad credentials', 'documentation_url': 'https://developer.github.com/v3'}
-------------||time:2019-09-09T15:45:50.664166+0600||level:ERROR||-------------
401 {'message': 'Bad credentials', 'documentation_url': 'https://developer.github.com/v3'}

github.GithubException.BadCredentialsException: 401 {'message': 'Bad credentials', 'documentation_url': 'https://developer.github.com/v3'}
-------------||time:2019-09-09T15:57:08.513488+0600||level:ERROR||-------------
401 {'message': 'Bad credentials', 'documentation_url': 'https://developer.github.com/v3'}

Traceback (most recent call last):
  File "/home/redowan/code/protomate/protomate/script.py", line 50, in <module>
    main()
  File "/home/redowan/code/protomate/protomate/script.py", line 43, in main
    g, user = authentication(github_username, github_password)
> File "/home/redowan/code/protomate/protomate/repo_auths.py", line 28, in authentication
    user.login
  File "/home/redowan/code/protomate/venv/lib/python3.7/site-packages/github/AuthenticatedUser.py", line 230, in login
    self._completeIfNotSet(self._login)
  File "/home/redowan/code/protomate/venv/lib/python3.7/site-packages/github/GithubObject.py", line 303, in _completeIfNotSet
    self._completeIfNeeded()
  File "/home/redowan/code/protomate/venv/lib/python3.7/site-packages/github/GithubObject.py", line 307, in _completeIfNeeded
    self.__complete()
  File "/home/redowan/code/protomate/venv/lib/python3.7/site-packages/github/GithubObject.py", line 310, in __complete
    headers, data = self._requester.requestJsonAndCheck("GET", self._url.value)
  File "/home/redowan/code/protomate/venv/lib/python3.7/site-packages/github/Requester.py", line 326, in requestJsonAndCheck
    verb, url, parameters, headers, input, self.__customConnection(url)
  File "/home/redowan/code/protomate/venv/lib/python3.7/site-packages/github/Requester.py", line 349, in __check
    raise self.__createException(status, responseHeaders, output)
github.GithubException.BadCredentialsException: 401 {'message': 'Bad credentials', 'documentation_url': 'https://developer.github.com/v3'}
-------------||time:2019-09-09T15:57:24.724709+0600||level:ERROR||-------------
401 {'message': 'Bad credentials', 'documentation_url': 'https://developer.github.com/v3'}

Traceback (most recent call last):
  File "/home/redowan/code/protomate/protomate/script.py", line 50, in <module>
    main()
  File "/home/redowan/code/protomate/protomate/script.py", line 43, in main
    g, user = authentication(github_username, github_password)
> File "/home/redowan/code/protomate/protomate/repo_auths.py", line 28, in authentication
    user.login
  File "/home/redowan/code/protomate/venv/lib/python3.7/site-packages/github/AuthenticatedUser.py", line 230, in login
    self._completeIfNotSet(self._login)
  File "/home/redowan/code/protomate/venv/lib/python3.7/site-packages/github/GithubObject.py", line 303, in _completeIfNotSet
    self._completeIfNeeded()
  File "/home/redowan/code/protomate/venv/lib/python3.7/site-packages/github/GithubObject.py", line 307, in _completeIfNeeded
    self.__complete()
  File "/home/redowan/code/protomate/venv/lib/python3.7/site-packages/github/GithubObject.py", line 310, in __complete
    headers, data = self._requester.requestJsonAndCheck("GET", self._url.value)
  File "/home/redowan/code/protomate/venv/lib/python3.7/site-packages/github/Requester.py", line 326, in requestJsonAndCheck
    verb, url, parameters, headers, input, self.__customConnection(url)
  File "/home/redowan/code/protomate/venv/lib/python3.7/site-packages/github/Requester.py", line 349, in __check
    raise self.__createException(status, responseHeaders, output)
github.GithubException.BadCredentialsException: 401 {'message': 'Bad credentials', 'documentation_url': 'https://developer.github.com/v3'}
